<?xml version="1.0" ?>
<!-- =================================================================================== -->
<!-- |    This document was autogenerated by xacro from src/ovis_ros2/src/ovis_description/urdf/ovis_standalone.urdf.xacro | -->
<!-- |    EDITING THIS FILE BY HAND IS NOT RECOMMENDED                                 | -->
<!-- =================================================================================== -->
<robot name="ovis" xmlns:body="http://playerstage.sourceforge.net/gazebo/xmlschema/#body" xmlns:controller="http://playerstage.sourceforge.net/gazebo/xmlschema/#controller" xmlns:gazebo="http://playerstage.sourceforge.net/gazebo/xmlschema/#gz" xmlns:geom="http://playerstage.sourceforge.net/gazebo/xmlschema/#geom" xmlns:interface="http://playerstage.sourceforge.net/gazebo/xmlschema/#interface" xmlns:joint="http://playerstage.sourceforge.net/gazebo/xmlschema/#joint" xmlns:model="http://playerstage.sourceforge.net/gazebo/xmlschema/#model" xmlns:physics="http://playerstage.sourceforge.net/gazebo/xmlschema/#physics" xmlns:renderable="http://playerstage.sourceforge.net/gazebo/xmlschema/#renderable" xmlns:rendering="http://playerstage.sourceforge.net/gazebo/xmlschema/#rendering" xmlns:sensor="http://playerstage.sourceforge.net/gazebo/xmlschema/#sensor" xmlns:xi="http://www.w3.org/2001/XInclude">
  <!-- links      		mesh_no
   base           		0
   shoulder       		1
   arm            		2
   forearm        		3
   wrist          		4
   arm_mico       		5
   arm_half1 (7dof)		6
   arm_half2 (7dof)		7
   wrist_spherical_1  8
   wrist_spherical_2  9

   hand 3 finger  		55
   hand_2finger   		56
   finger_proximal		57
   finger_distal      58
-->
  <!-- <xacro:include filename="$(find ovis_description)/urdf/kinova_finger_set.xacro" /> -->
  <!-- Import all Gazebo-customization elements -->
  <!-- <xacro:include filename="$(find ovis_description)/urdf/ovis.gazebo" /> -->
  <link name="base_link"/>
  <!-- for gazebo -->
  <!-- <link name="world" /> -->
  <!-- <joint name="connect_root_and_world" type="fixed">
        <child link="root" />
        <parent link="world" />
        <origin xyz="0 0 0" rpy="0 0 0" />
    </joint> -->
  <!-- <xacro:gazebo_config robot_namespace="${prefix}" /> -->
  <link name="ovis_link_base">
    <visual>
      <geometry>
        <mesh filename="file:///home/capra/rove/rove/install/ovis_description/share/ovis_description/meshes/visual/ovis_base.stl"/>
      </geometry>
      <material name="carbon_fiber">
        <color rgba="0.792156862745098 0 0 1"/>
      </material>
    </visual>
    <collision>
      <geometry>
        <mesh filename="file:///home/capra/rove/rove/install/ovis_description/share/ovis_description/meshes/collision/ovis_base.stl"/>
      </geometry>
    </collision>
    <inertial>
      <mass value="0.46784"/>
      <origin rpy="0 0 0" xyz="0 0 0.1255"/>
      <inertia ixx="0.000951270861568" ixy="0" ixz="0" iyy="0.000951270861568" iyz="0" izz="0.00037427200000000004"/>
    </inertial>
  </link>
  <joint name="ovis_joint_base" type="fixed">
    <parent link="base_link"/>
    <child link="ovis_link_base"/>
    <axis xyz="0 0 0"/>
    <origin rpy="1.5707963267948966 0 0" xyz="0 0 0"/>
    <dynamics damping="0.0" friction="0.0"/>
  </joint>
  <link name="ovis_link_1">
    <visual>
      <geometry>
        <mesh filename="file:///home/capra/rove/rove/install/ovis_description/share/ovis_description/meshes/visual/ovis_shoulder.stl"/>
      </geometry>
      <material name="carbon_fiber">
        <color rgba="0.792156862745098 0 0 1"/>
      </material>
    </visual>
    <collision>
      <geometry>
        <mesh filename="file:///home/capra/rove/rove/install/ovis_description/share/ovis_description/meshes/collision/ovis_shoulder.stl"/>
      </geometry>
    </collision>
    <inertial>
      <mass value="0.7477"/>
      <origin xyz="0 -0.002 -0.0605"/>
      <inertia ixx="0.0015203172520400004" ixy="0" ixz="0" iyy="0.0015203172520400004" iyz="0" izz="0.00059816"/>
    </inertial>
  </link>
  <joint name="ovis_joint_1" type="continuous">
    <parent link="ovis_link_base"/>
    <child link="ovis_link_1"/>
    <axis xyz="0 1 0"/>
    <limit effort="40" velocity="0.6283185307179586"/>
    <origin rpy="0 0 0" xyz="0 0.051 0"/>
    <dynamics damping="0.0" friction="0.0"/>
  </joint>
  <transmission name="ovis_joint_1_trans">
    <type>transmission_interface/SimpleTransmission</type>
    <joint name="ovis_joint_1">
      <hardwareInterface>hardware_interface/EffortJointInterface</hardwareInterface>
    </joint>
    <actuator name="ovis_joint_1_actuator">
      <hardwareInterface>hardware_interface/EffortJointInterface</hardwareInterface>
      <mechanicalReduction>160</mechanicalReduction>
    </actuator>
  </transmission>
  <!--For torque sensing in simulation-->
  <gazebo reference="ovis_joint_1">
    <provideFeedback>true</provideFeedback>
  </gazebo>
  <gazebo reference="ovis_joint_1">
    <sensor name="force_torque_sensor" type="force_torque">
      <always_on>true</always_on>
      <update_rate>30</update_rate>
      <visualize>true</visualize>
      <topic>ovis_joint_1/force_torque</topic>
      <force_torque>
        <frame>sensor</frame>
        <measure_direction>parent_to_child</measure_direction>
      </force_torque>
    </sensor>
  </gazebo>
  <!-- <gazebo>
        <plugin name="ft_sensor" filename="libgazebo_ros_ft_sensor.so">
          <updateRate>30.0</updateRate>
          <topicName>${joint_name}_ft_sensor_topic</topicName>
          <jointName>${joint_name}</jointName>
        </plugin>
      </gazebo> -->
  <link name="ovis_link_2">
    <visual>
      <geometry>
        <mesh filename="file:///home/capra/rove/rove/install/ovis_description/share/ovis_description/meshes/visual/ovis_upper_arm.stl"/>
      </geometry>
      <material name="carbon_fiber">
        <color rgba="0.792156862745098 0 0 1"/>
      </material>
    </visual>
    <collision>
      <geometry>
        <mesh filename="file:///home/capra/rove/rove/install/ovis_description/share/ovis_description/meshes/collision/ovis_upper_arm.stl"/>
      </geometry>
    </collision>
    <inertial>
      <mass value="0.99"/>
      <origin xyz="0 -0.2065 -0.01"/>
      <inertia ixx="0.010502207990999999" ixy="0" ixz="0" iyy="0.0007920000000000001" iyz="0" izz="0.010502207990999999"/>
    </inertial>
  </link>
  <joint name="ovis_joint_2" type="revolute">
    <parent link="ovis_link_1"/>
    <child link="ovis_link_2"/>
    <axis xyz="0 0 1"/>
    <limit effort="80" lower="0" upper="3.141592653589793" velocity="0.6283185307179586"/>
    <origin rpy="0 0 -1.5707963267948966" xyz="0 0.0889 0"/>
    <dynamics damping="0.0" friction="0.0"/>
  </joint>
  <transmission name="ovis_joint_2_trans">
    <type>transmission_interface/SimpleTransmission</type>
    <joint name="ovis_joint_2">
      <hardwareInterface>hardware_interface/EffortJointInterface</hardwareInterface>
    </joint>
    <actuator name="ovis_joint_2_actuator">
      <hardwareInterface>hardware_interface/EffortJointInterface</hardwareInterface>
      <mechanicalReduction>160</mechanicalReduction>
    </actuator>
  </transmission>
  <!--For torque sensing in simulation-->
  <gazebo reference="ovis_joint_2">
    <provideFeedback>true</provideFeedback>
  </gazebo>
  <gazebo reference="ovis_joint_2">
    <sensor name="force_torque_sensor" type="force_torque">
      <always_on>true</always_on>
      <update_rate>30</update_rate>
      <visualize>true</visualize>
      <topic>ovis_joint_2/force_torque</topic>
      <force_torque>
        <frame>sensor</frame>
        <measure_direction>parent_to_child</measure_direction>
      </force_torque>
    </sensor>
  </gazebo>
  <!-- <gazebo>
        <plugin name="ft_sensor" filename="libgazebo_ros_ft_sensor.so">
          <updateRate>30.0</updateRate>
          <topicName>${joint_name}_ft_sensor_topic</topicName>
          <jointName>${joint_name}</jointName>
        </plugin>
      </gazebo> -->
  <link name="ovis_link_3">
    <visual>
      <geometry>
        <mesh filename="file:///home/capra/rove/rove/install/ovis_description/share/ovis_description/meshes/visual/ovis_elbow.stl"/>
      </geometry>
      <material name="carbon_fiber">
        <color rgba="0.792156862745098 0 0 1"/>
      </material>
    </visual>
    <collision>
      <geometry>
        <mesh filename="file:///home/capra/rove/rove/install/ovis_description/share/ovis_description/meshes/collision/ovis_elbow.stl"/>
      </geometry>
    </collision>
    <inertial>
      <mass value="0.6763"/>
      <origin xyz="0 0.081 -0.0086"/>
      <inertia ixx="0.0014202243190800001" ixy="0" ixz="0" iyy="0.000304335" iyz="0" izz="0.0014202243190800001"/>
    </inertial>
  </link>
  <joint name="ovis_joint_3" type="revolute">
    <parent link="ovis_link_2"/>
    <child link="ovis_link_3"/>
    <axis xyz="0 0 1"/>
    <limit effort="40" lower="-3.141592653589793" upper="0" velocity="0.6283185307179586"/>
    <origin rpy="0 0 3.141592653589793" xyz="0 0.465 0"/>
    <dynamics damping="0.0" friction="0.0"/>
  </joint>
  <transmission name="ovis_joint_3_trans">
    <type>transmission_interface/SimpleTransmission</type>
    <joint name="ovis_joint_3">
      <hardwareInterface>hardware_interface/EffortJointInterface</hardwareInterface>
    </joint>
    <actuator name="ovis_joint_3_actuator">
      <hardwareInterface>hardware_interface/EffortJointInterface</hardwareInterface>
      <mechanicalReduction>160</mechanicalReduction>
    </actuator>
  </transmission>
  <!--For torque sensing in simulation-->
  <gazebo reference="ovis_joint_3">
    <provideFeedback>true</provideFeedback>
  </gazebo>
  <gazebo reference="ovis_joint_3">
    <sensor name="force_torque_sensor" type="force_torque">
      <always_on>true</always_on>
      <update_rate>30</update_rate>
      <visualize>true</visualize>
      <topic>ovis_joint_3/force_torque</topic>
      <force_torque>
        <frame>sensor</frame>
        <measure_direction>parent_to_child</measure_direction>
      </force_torque>
    </sensor>
  </gazebo>
  <!-- <gazebo>
        <plugin name="ft_sensor" filename="libgazebo_ros_ft_sensor.so">
          <updateRate>30.0</updateRate>
          <topicName>${joint_name}_ft_sensor_topic</topicName>
          <jointName>${joint_name}</jointName>
        </plugin>
      </gazebo> -->
  <link name="ovis_link_4">
    <visual>
      <geometry>
        <mesh filename="file:///home/capra/rove/rove/install/ovis_description/share/ovis_description/meshes/visual/ovis_forearm.stl"/>
      </geometry>
      <material name="carbon_fiber">
        <color rgba="0.792156862745098 0 0 1"/>
      </material>
    </visual>
    <collision>
      <geometry>
        <mesh filename="file:///home/capra/rove/rove/install/ovis_description/share/ovis_description/meshes/collision/ovis_forearm.stl"/>
      </geometry>
    </collision>
    <inertial>
      <mass value="0.426367"/>
      <origin xyz="0 -0.037 -0.0642"/>
      <inertia ixx="7.734969059999999e-05" ixy="0" ixz="0" iyy="7.734969059999999e-05" iyz="0" izz="0.0001428"/>
    </inertial>
  </link>
  <joint name="ovis_joint_4" type="continuous">
    <parent link="ovis_link_3"/>
    <child link="ovis_link_4"/>
    <axis xyz="0 1 0"/>
    <limit effort="20" velocity="0.8377580409572781"/>
    <origin rpy="0 0 0" xyz="0.0889 0.047625 0"/>
    <dynamics damping="0.0" friction="0.0"/>
  </joint>
  <transmission name="ovis_joint_4_trans">
    <type>transmission_interface/SimpleTransmission</type>
    <joint name="ovis_joint_4">
      <hardwareInterface>hardware_interface/EffortJointInterface</hardwareInterface>
    </joint>
    <actuator name="ovis_joint_4_actuator">
      <hardwareInterface>hardware_interface/EffortJointInterface</hardwareInterface>
      <mechanicalReduction>160</mechanicalReduction>
    </actuator>
  </transmission>
  <!--For torque sensing in simulation-->
  <gazebo reference="ovis_joint_4">
    <provideFeedback>true</provideFeedback>
  </gazebo>
  <gazebo reference="ovis_joint_4">
    <sensor name="force_torque_sensor" type="force_torque">
      <always_on>true</always_on>
      <update_rate>30</update_rate>
      <visualize>true</visualize>
      <topic>ovis_joint_4/force_torque</topic>
      <force_torque>
        <frame>sensor</frame>
        <measure_direction>parent_to_child</measure_direction>
      </force_torque>
    </sensor>
  </gazebo>
  <!-- <gazebo>
        <plugin name="ft_sensor" filename="libgazebo_ros_ft_sensor.so">
          <updateRate>30.0</updateRate>
          <topicName>${joint_name}_ft_sensor_topic</topicName>
          <jointName>${joint_name}</jointName>
        </plugin>
      </gazebo> -->
  <link name="ovis_link_5">
    <visual>
      <geometry>
        <mesh filename="file:///home/capra/rove/rove/install/ovis_description/share/ovis_description/meshes/visual/ovis_wrist.stl"/>
      </geometry>
      <material name="carbon_fiber">
        <color rgba="0.792156862745098 0 0 1"/>
      </material>
    </visual>
    <collision>
      <geometry>
        <mesh filename="file:///home/capra/rove/rove/install/ovis_description/share/ovis_description/meshes/collision/ovis_wrist.stl"/>
      </geometry>
    </collision>
    <inertial>
      <mass value="0.85968"/>
      <origin xyz="0 -0.145  -0.0076"/>
      <inertia ixx="0.004670909316288" ixy="0" ixz="0" iyy="0.00038685599999999993" iyz="0" izz="0.004670909316288"/>
    </inertial>
  </link>
  <joint name="ovis_joint_5" type="revolute">
    <parent link="ovis_link_4"/>
    <child link="ovis_link_5"/>
    <axis xyz="0 0 1"/>
    <limit effort="20" lower="-1.5707963267948966" upper="1.5707963267948966" velocity="0.8377580409572781"/>
    <origin rpy="0 0 0" xyz="0 0.265 0"/>
    <dynamics damping="0.0" friction="0.0"/>
  </joint>
  <transmission name="ovis_joint_5_trans">
    <type>transmission_interface/SimpleTransmission</type>
    <joint name="ovis_joint_5">
      <hardwareInterface>hardware_interface/EffortJointInterface</hardwareInterface>
    </joint>
    <actuator name="ovis_joint_5_actuator">
      <hardwareInterface>hardware_interface/EffortJointInterface</hardwareInterface>
      <mechanicalReduction>160</mechanicalReduction>
    </actuator>
  </transmission>
  <!--For torque sensing in simulation-->
  <gazebo reference="ovis_joint_5">
    <provideFeedback>true</provideFeedback>
  </gazebo>
  <gazebo reference="ovis_joint_5">
    <sensor name="force_torque_sensor" type="force_torque">
      <always_on>true</always_on>
      <update_rate>30</update_rate>
      <visualize>true</visualize>
      <topic>ovis_joint_5/force_torque</topic>
      <force_torque>
        <frame>sensor</frame>
        <measure_direction>parent_to_child</measure_direction>
      </force_torque>
    </sensor>
  </gazebo>
  <!-- <gazebo>
        <plugin name="ft_sensor" filename="libgazebo_ros_ft_sensor.so">
          <updateRate>30.0</updateRate>
          <topicName>${joint_name}_ft_sensor_topic</topicName>
          <jointName>${joint_name}</jointName>
        </plugin>
      </gazebo> -->
  <link name="ovis_link_6">
    <visual>
      <geometry>
        <mesh filename="file:///home/capra/rove/rove/install/ovis_description/share/ovis_description/meshes/visual/ovis_flange.stl"/>
      </geometry>
      <material name="carbon_fiber">
        <color rgba="0.792156862745098 0 0 1"/>
      </material>
    </visual>
    <collision>
      <geometry>
        <mesh filename="file:///home/capra/rove/rove/install/ovis_description/share/ovis_description/meshes/collision/ovis_flange.stl"/>
      </geometry>
    </collision>
    <inertial>
      <mass value="0.8447"/>
      <origin xyz="0 -0.103563213 0"/>
      <inertia ixx="0.00247073761701" ixy="0" ixz="0" iyy="0.000380115" iyz="0" izz="0.00247073761701"/>
    </inertial>
  </link>
  <joint name="ovis_joint_6" type="continuous">
    <parent link="ovis_link_5"/>
    <child link="ovis_link_6"/>
    <axis xyz="0 0 1"/>
    <limit effort="20" velocity="0.8377580409572781"/>
    <origin rpy="1.5707963267948966 1.5707963267948966 0" xyz="0 0.0762 0"/>
    <dynamics damping="0.0" friction="0.0"/>
  </joint>
  <transmission name="ovis_joint_6_trans">
    <type>transmission_interface/SimpleTransmission</type>
    <joint name="ovis_joint_6">
      <hardwareInterface>hardware_interface/EffortJointInterface</hardwareInterface>
    </joint>
    <actuator name="ovis_joint_6_actuator">
      <hardwareInterface>hardware_interface/EffortJointInterface</hardwareInterface>
      <mechanicalReduction>160</mechanicalReduction>
    </actuator>
  </transmission>
  <!--For torque sensing in simulation-->
  <gazebo reference="ovis_joint_6">
    <provideFeedback>true</provideFeedback>
  </gazebo>
  <gazebo reference="ovis_joint_6">
    <sensor name="force_torque_sensor" type="force_torque">
      <always_on>true</always_on>
      <update_rate>30</update_rate>
      <visualize>true</visualize>
      <topic>ovis_joint_6/force_torque</topic>
      <force_torque>
        <frame>sensor</frame>
        <measure_direction>parent_to_child</measure_direction>
      </force_torque>
    </sensor>
  </gazebo>
  <!-- <gazebo>
        <plugin name="ft_sensor" filename="libgazebo_ros_ft_sensor.so">
          <updateRate>30.0</updateRate>
          <topicName>${joint_name}_ft_sensor_topic</topicName>
          <jointName>${joint_name}</jointName>
        </plugin>
      </gazebo> -->
  <link name="ovis_end_effector"/>
  <joint name="ovis_joint_end_effector" type="fixed">
    <parent link="ovis_link_6"/>
    <child link="ovis_end_effector"/>
    <axis xyz="0 0 0"/>
    <origin rpy="3.141592653589793 0 1.5707963267948966" xyz="0 0 -0.1600"/>
  </joint>
  <!-- <xacro:kinova_3fingers link_hand="${prefix}_link_6" prefix="${prefix}_"/> -->
  <!-- <xacro:ovis_ros2_control name="ovis" prefix="${prefix}" /> -->
</robot>
