<!-- Generated by Phobos (blender addon) -->

<robot name="ovis2" version="1.0">
  <joint name="ovis2_joint_1" type="continuous">
    <limit lower="0.00000" upper="0.00000" effort="30.50000" velocity="0.00000"/>
    <origin rpy="0.00000 0.00000 0.00000" xyz="0.00000 0.00000 0.03000"/>
    <parent link="ovis2_base_link"/>
    <child link="ovis2_link_1"/>
    <axis xyz="0.00000 0.00000 1.00000"/>
  </joint>
  <joint name="ovis2_joint_2" type="revolute">
    <limit lower="-3.40339" upper="0.26180" effort="30.50000" velocity="0.62832"/>
    <origin rpy="0.00000 0.00000 0.00000" xyz="0.00004 0.06250 0.07001"/>
    <parent link="ovis2_link_1"/>
    <child link="ovis2_link_2"/>
    <axis xyz="0.00000 1.00000 0.00000"/>
  </joint>
  <joint name="ovis2_joint_3" type="revolute">
    <limit lower="-5.23599" upper="0.00000" effort="30.50000" velocity="0.62832"/>
    <origin rpy="0.00000 0.00000 0.00000" xyz="0.30039 -0.01763 0.00072"/>
    <parent link="ovis2_link_2"/>
    <child link="ovis2_link_3"/>
    <axis xyz="0.00000 -1.00000 0.00000"/>
  </joint>
  <joint name="ovis2_joint_4" type="continuous">
    <limit lower="0.00000" upper="0.00000" effort="20.00000" velocity="0.83776"/>
    <origin rpy="0.00000 0.00000 0.00000" xyz="-0.06672 -0.04897 -0.00044"/>
    <parent link="ovis2_link_3"/>
    <child link="ovis2_link_4"/>
    <axis xyz="-1.00000 0.00000 0.00000"/>
  </joint>
  <joint name="ovis2_joint_5" type="revolute">
    <limit lower="-1.65806" upper="1.65806" effort="20.00000" velocity="0.83776"/>
    <origin rpy="0.00000 0.00000 0.00000" xyz="-0.33480 0.00015 0.00051"/>
    <parent link="ovis2_link_4"/>
    <child link="ovis2_link_5"/>
    <axis xyz="0.00000 1.00000 0.00000"/>
  </joint>
  <joint name="ovis2_joint_6" type="continuous">
    <limit lower="0.00000" upper="0.00000" effort="20.00000" velocity="0.83776"/>
    <origin rpy="0.00000 0.00000 0.00000" xyz="-0.07000 0.00003 0.00001"/>
    <parent link="ovis2_link_5"/>
    <child link="ovis2_link_6"/>
    <axis xyz="-1.00000 0.00000 0.00000"/>
  </joint>
  <link name="ovis2_base_link">
    <collision name="ovis2_base_col">
      <origin rpy="0.00000 0.00000 0.00000" xyz="0.00000 0.00000 0.00000"/>
      <geometry>
        <mesh filename="../meshes/stl/Low res ovis.025.stl" scale="1.00000 1.00000 1.00000"/>
      </geometry>
    </collision>
    <inertial>
      <inertia ixx="0.00001" ixy="0.00000" ixz="0.00000" iyy="0.00001" iyz="0.00000" izz="0.00001"/>
      <origin rpy="0.00000 0.00000 0.00000" xyz="0.00000 0.00000 0.00000"/>
      <mass value="0.00001"/>
    </inertial>
    <sensor name="ovis2_base_6dof" type="force_torque">
      <parent link="ovis2_base_link"/>
      <force_torque>
        <frame>ovis2_base_link</frame>
      </force_torque>
    </sensor>
    <visual name="ovis2_base_vis">
      <origin rpy="0.00000 0.00000 0.00000" xyz="0.00000 0.00000 -0.00000"/>
      <material name="Opaque(128,128,128)"/>
      <geometry>
        <mesh filename="../meshes/stl/Low res ovis.011.stl" scale="1.00000 1.00000 1.00000"/>
      </geometry>
    </visual>
  </link>
  <link name="ovis2_link_1">
    <collision name="ovis2_j12_col">
      <origin rpy="0.00000 0.00000 0.00000" xyz="0.00000 0.00000 0.00000"/>
      <geometry>
        <mesh filename="../meshes/stl/Low res ovis.026.stl" scale="1.00000 1.00000 1.00000"/>
      </geometry>
    </collision>
    <inertial>
      <inertia ixx="0.00001" ixy="0.00000" ixz="0.00000" iyy="0.00001" iyz="0.00000" izz="0.00001"/>
      <origin rpy="0.00000 0.00000 0.00000" xyz="0.00000 0.00000 0.00000"/>
      <mass value="0.00001"/>
    </inertial>
    <visual name="ovis2_j12_vis">
      <origin rpy="0.00000 0.00000 0.00000" xyz="0.00000 0.00000 -0.00000"/>
      <material name="Opaque(128,128,128)"/>
      <geometry>
        <mesh filename="../meshes/stl/Low res ovis.019.stl" scale="1.00000 1.00000 1.00000"/>
      </geometry>
    </visual>
  </link>
  <link name="ovis2_link_2">
    <collision name="ovis2_j23_col">
      <origin rpy="0.00000 0.00000 0.00000" xyz="-0.00000 -0.00000 0.00000"/>
      <geometry>
        <mesh filename="../meshes/stl/Low res ovis.028.stl" scale="1.00000 1.00000 1.00000"/>
      </geometry>
    </collision>
    <inertial>
      <inertia ixx="0.00001" ixy="0.00000" ixz="0.00000" iyy="0.00001" iyz="0.00000" izz="0.00001"/>
      <origin rpy="0.00000 0.00000 0.00000" xyz="0.00000 0.00000 0.00000"/>
      <mass value="0.00001"/>
    </inertial>
    <visual name="ovis2_j23_vis">
      <origin rpy="0.00000 0.00000 0.00000" xyz="-0.00000 0.00000 0.00000"/>
      <material name="Aluminum_-_Satin"/>
      <geometry>
        <mesh filename="../meshes/stl/Low res ovis.020.stl" scale="1.00000 1.00000 1.00000"/>
      </geometry>
    </visual>
  </link>
  <link name="ovis2_link_3">
    <collision name="ovis2_j34_col">
      <origin rpy="0.00000 -0.00000 0.00000" xyz="-0.00000 -0.00000 0.00000"/>
      <geometry>
        <mesh filename="../meshes/stl/Low res ovis.029.stl" scale="1.00000 1.00000 1.00000"/>
      </geometry>
    </collision>
    <inertial>
      <inertia ixx="0.00001" ixy="0.00000" ixz="0.00000" iyy="0.00001" iyz="0.00000" izz="0.00001"/>
      <origin rpy="0.00000 0.00000 0.00000" xyz="0.00000 0.00000 0.00000"/>
      <mass value="0.00001"/>
    </inertial>
    <visual name="ovis2_j34_vis">
      <origin rpy="0.00000 0.00000 0.00000" xyz="0.00000 0.00000 -0.00000"/>
      <material name="Opaque(128,128,128)"/>
      <geometry>
        <mesh filename="../meshes/stl/Low res ovis.021.stl" scale="1.00000 1.00000 1.00000"/>
      </geometry>
    </visual>
  </link>
  <link name="ovis2_link_4">
    <collision name="ovis2_j45_col">
      <origin rpy="0.00000 -0.00000 0.00000" xyz="-0.00000 0.00000 0.00000"/>
      <geometry>
        <mesh filename="../meshes/stl/Low res ovis.030.stl" scale="1.00000 1.00000 1.00000"/>
      </geometry>
    </collision>
    <inertial>
      <inertia ixx="0.00001" ixy="0.00000" ixz="0.00000" iyy="0.00001" iyz="0.00000" izz="0.00001"/>
      <origin rpy="0.00000 0.00000 0.00000" xyz="0.00000 0.00000 0.00000"/>
      <mass value="0.00001"/>
    </inertial>
    <visual name="ovis2_j45_vis">
      <origin rpy="0.00000 0.00000 0.00000" xyz="-0.00000 0.00000 -0.00000"/>
      <material name="Opaque(128,128,128)"/>
      <geometry>
        <mesh filename="../meshes/stl/Low res ovis.022.stl" scale="1.00000 1.00000 1.00000"/>
      </geometry>
    </visual>
  </link>
  <link name="ovis2_link_5">
    <collision name="ovis2_j56_COL">
      <origin rpy="0.00000 -0.00000 0.00000" xyz="0.00000 -0.00000 0.00000"/>
      <geometry>
        <mesh filename="../meshes/stl/Low res ovis.031.stl" scale="1.00000 1.00000 1.00000"/>
      </geometry>
    </collision>
    <inertial>
      <inertia ixx="0.00001" ixy="0.00000" ixz="0.00000" iyy="0.00001" iyz="0.00000" izz="0.00001"/>
      <origin rpy="0.00000 0.00000 0.00000" xyz="0.00000 0.00000 0.00000"/>
      <mass value="0.00001"/>
    </inertial>
    <visual name="ovis2_j56_vis">
      <origin rpy="0.00000 0.00000 0.00000" xyz="0.00000 -0.00000 0.00000"/>
      <material name="Opaque(128,128,128)"/>
      <geometry>
        <mesh filename="../meshes/stl/Low res ovis.023.stl" scale="1.00000 1.00000 1.00000"/>
      </geometry>
    </visual>
  </link>
  <link name="ovis2_link_6">
    <collision name="ovis2_end_effector_col">
      <origin rpy="0.00000 -0.00000 0.00000" xyz="0.00000 -0.00000 0.00000"/>
      <geometry>
        <mesh filename="../meshes/stl/Low res ovis.033.stl" scale="1.00000 1.00000 1.00000"/>
      </geometry>
    </collision>
    <inertial>
      <inertia ixx="0.00001" ixy="0.00000" ixz="0.00000" iyy="0.00001" iyz="0.00000" izz="0.00001"/>
      <origin rpy="0.00000 0.00000 0.00000" xyz="0.00000 0.00000 0.00000"/>
      <mass value="0.00001"/>
    </inertial>
    <visual name="ovis2_end_effector_vis">
      <origin rpy="0.00000 0.00000 0.00000" xyz="0.00000 0.00000 0.00000"/>
      <material name="Opaque(128,128,128)"/>
      <geometry>
        <mesh filename="../meshes/stl/Low res ovis.024.stl" scale="1.00000 1.00000 1.00000"/>
      </geometry>
    </visual>
  </link>
  <material name="Aluminum_-_Satin">
    <color rgba="0.80000 0.80000 0.80000 1.00000"/>
  </material>
  <material name="Opaque(128,128,128)">
    <color rgba="0.80000 0.80000 0.80000 1.00000"/>
  </material>
</robot>