<!-- Generated by Phobos (blender addon) -->

<robot name="ovis2" version="1.0">
  <joint name="ovis2_joint_1" type="continuous">
    <limit lower="0.00000" upper="0.00000" effort="30.50000" velocity="0.00000"/>
    <origin rpy="0.00000 0.00000 0.00000" xyz="0.00000 0.00000 0.03000"/>
    <parent link="ovis2_base_link"/>
    <child link="ovis2_link_1"/>
    <axis xyz="0.00000 0.00000 1.00000"/>
  </joint>
  <joint name="ovis2_joint_2" type="revolute">
    <limit lower="-3.40339" upper="0.26180" effort="30.50000" velocity="0.62832"/>
    <origin rpy="0.00000 0.00000 0.00000" xyz="0.00004 0.06250 0.07001"/>
    <parent link="ovis2_link_1"/>
    <child link="ovis2_link_2"/>
    <axis xyz="0.00000 1.00000 0.00000"/>
  </joint>
  <joint name="ovis2_joint_3" type="revolute">
    <limit lower="-5.23599" upper="0.00000" effort="30.50000" velocity="0.62832"/>
    <origin rpy="0.00000 0.00000 0.00000" xyz="0.30039 -0.01763 0.00072"/>
    <parent link="ovis2_link_2"/>
    <child link="ovis2_link_3"/>
    <axis xyz="0.00000 -1.00000 0.00000"/>
  </joint>
  <joint name="ovis2_joint_4" type="continuous">
    <limit lower="0.00000" upper="0.00000" effort="20.00000" velocity="0.83776"/>
    <origin rpy="0.00000 0.00000 0.00000" xyz="-0.06672 -0.04897 -0.00044"/>
    <parent link="ovis2_link_3"/>
    <child link="ovis2_link_4"/>
    <axis xyz="-1.00000 0.00000 0.00000"/>
  </joint>
  <joint name="ovis2_joint_5" type="revolute">
    <limit lower="-1.65806" upper="1.65806" effort="20.00000" velocity="0.83776"/>
    <origin rpy="0.00000 0.00000 0.00000" xyz="-0.33480 0.00015 0.00051"/>
    <parent link="ovis2_link_4"/>
    <child link="ovis2_link_5"/>
    <axis xyz="0.00000 1.00000 0.00000"/>
  </joint>
  <joint name="ovis2_joint_6" type="continuous">
    <limit lower="0.00000" upper="0.00000" effort="20.00000" velocity="0.83776"/>
    <origin rpy="0.00000 0.00000 0.00000" xyz="-0.07000 0.00003 0.00001"/>
    <parent link="ovis2_link_5"/>
    <child link="ovis2_link_6"/>
    <axis xyz="-1.00000 0.00000 0.00000"/>
  </joint>
  
 <!-- Base link -->
  <link name="ovis2_base_link">
    <collision name="ovis2_base_col">
      <origin rpy="0 0 0" xyz="0 0 0"/>
      <geometry>
        <mesh filename="file://$(find ovis_description)/urdf/ovis2/meshes/collision/ovis_base.stl" scale="1 1 1"/>
      </geometry>
    </collision>
    <inertial>
      <inertia ixx="0.00001" ixy="0" ixz="0" iyy="0.00001" iyz="0" izz="0.00001"/>
      <origin rpy="0 0 0" xyz="0 0 0"/>
      <mass value="0.00001"/>
    </inertial>
    <visual name="ovis2_base_vis">
      <origin rpy="0 0 0" xyz="0 0 0"/>
      <material name="Opaque(128,128,128)"/>
      <geometry>
        <mesh filename="file://$(find ovis_description)/urdf/ovis2/meshes/collision/ovis_base.stl" scale="1 1 1"/>
      </geometry>
    </visual>
  </link>
  
  <!-- Link 1 -->
  <link name="ovis2_link_1">
    <collision name="ovis2_j12_col">
      <origin rpy="0 0 0" xyz="0 0 0"/>
      <geometry>
        <mesh filename="file://$(find ovis_description)/urdf/ovis2/meshes/collision/ovis_j12.stl" scale="1 1 1"/>
      </geometry>
    </collision>
    <inertial>
      <inertia ixx="0.00001" ixy="0" ixz="0" iyy="0.00001" iyz="0" izz="0.00001"/>
      <origin rpy="0 0 0" xyz="0 0 0"/>
      <mass value="0.00001"/>
    </inertial>
    <visual name="ovis2_j12_vis">
      <origin rpy="0 0 0" xyz="0 0 0"/>
      <material name="Opaque(128,128,128)"/>
      <geometry>
        <mesh filename="file://$(find ovis_description)/urdf/ovis2/meshes/collision/ovis_j12.stl" scale="1 1 1"/>
      </geometry>
    </visual>
  </link>
  
  <!-- Link 2 -->
  <link name="ovis2_link_2">
    <collision name="ovis2_j23_col">
      <origin rpy="0 0 0" xyz="0 0 0"/>
      <geometry>
        <mesh filename="file://$(find ovis_description)/urdf/ovis2/meshes/collision/ovis_j23.stl" scale="1 1 1"/>
      </geometry>
    </collision>
    <inertial>
      <inertia ixx="0.00001" ixy="0" ixz="0" iyy="0.00001" iyz="0" izz="0.00001"/>
      <origin rpy="0 0 0" xyz="0 0 0"/>
      <mass value="0.00001"/>
    </inertial>
    <visual name="ovis2_j23_vis">
      <origin rpy="0 0 0" xyz="0 0 0"/>
      <material name="Aluminum_-_Satin"/>
      <geometry>
        <mesh filename="file://$(find ovis_description)/urdf/ovis2/meshes/collision/ovis_j23.stl" scale="1 1 1"/>
      </geometry>
    </visual>
  </link>
  
  <!-- Link 3 -->
  <link name="ovis2_link_3">
    <collision name="ovis2_j34_col">
      <origin rpy="0 0 0" xyz="0 0 0"/>
      <geometry>
        <mesh filename="file://$(find ovis_description)/urdf/ovis2/meshes/collision/ovis_j34.stl" scale="1 1 1"/>
      </geometry>
    </collision>
    <inertial>
      <inertia ixx="0.00001" ixy="0" ixz="0" iyy="0.00001" iyz="0" izz="0.00001"/>
      <origin rpy="0 0 0" xyz="0 0 0"/>
      <mass value="0.00001"/>
    </inertial>
    <visual name="ovis2_j34_vis">
      <origin rpy="0 0 0" xyz="0 0 0"/>
      <material name="Opaque(128,128,128)"/>
      <geometry>
        <mesh filename="file://$(find ovis_description)/urdf/ovis2/meshes/collision/ovis_j34.stl" scale="1 1 1"/>
      </geometry>
    </visual>
  </link>
  
  <!-- Link 4 -->
  <link name="ovis2_link_4">
    <collision name="ovis2_j45_col">
      <origin rpy="0 0 0" xyz="0 0 0"/>
      <geometry>
        <mesh filename="file://$(find ovis_description)/urdf/ovis2/meshes/collision/ovis_j45.stl" scale="1 1 1"/>
      </geometry>
    </collision>
    <inertial>
      <inertia ixx="0.00001" ixy="0" ixz="0" iyy="0.00001" iyz="0" izz="0.00001"/>
      <origin rpy="0 0 0" xyz="0 0 0"/>
      <mass value="0.00001"/>
    </inertial>
    <visual name="ovis2_j45_vis">
      <origin rpy="0 0 0" xyz="0 0 0"/>
      <material name="Opaque(128,128,128)"/>
      <geometry>
        <mesh filename="file://$(find ovis_description)/urdf/ovis2/meshes/collision/ovis_j45.stl" scale="1 1 1"/>
      </geometry>
    </visual>
  </link>
  
  <!-- Link 5 -->
  <link name="ovis2_link_5">
    <collision name="ovis2_j56_col">
      <origin rpy="0 0 0" xyz="0 0 0"/>
      <geometry>
        <mesh filename="file://$(find ovis_description)/urdf/ovis2/meshes/collision/ovis_j56.stl" scale="1 1 1"/>
      </geometry>
    </collision>
    <inertial>
      <inertia ixx="0.00001" ixy="0" ixz="0" iyy="0.00001" iyz="0" izz="0.00001"/>
      <origin rpy="0 0 0" xyz="0 0 0"/>
      <mass value="0.00001"/>
    </inertial>
    <visual name="ovis2_j56_vis">
      <origin rpy="0 0 0" xyz="0 0 0"/>
      <material name="Opaque(128,128,128)"/>
      <geometry>
        <mesh filename="file://$(find ovis_description)/urdf/ovis2/meshes/collision/ovis_j56.stl" scale="1 1 1"/>
      </geometry>
    </visual>
  </link>
  
  <!-- Link 6 -->
  <link name="ovis2_link_6">
    <collision name="ovis2_end_effector_col">
      <origin rpy="0 0 0" xyz="0 0 0"/>
      <geometry>
        <mesh filename="file://$(find ovis_description)/urdf/ovis2/meshes/collision/ovis_end_effector.stl" scale="1 1 1"/>
      </geometry>
    </collision>
    <inertial>
      <inertia ixx="0.00001" ixy="0" ixz="0" iyy="0.00001" iyz="0" izz="0.00001"/>
      <origin rpy="0 0 0" xyz="0 0 0"/>
      <mass value="0.00001"/>
    </inertial>
    <visual name="ovis2_end_effector_vis">
      <origin rpy="0 0 0" xyz="0 0 0"/>
      <material name="Opaque(128,128,128)"/>
      <geometry>
        <mesh filename="file://$(find ovis_description)/urdf/ovis2/meshes/collision/ovis_end_effector.stl" scale="1 1 1"/>
      </geometry>
    </visual>
  </link>
  
  <material name="Aluminum_-_Satin">
    <color rgba="0.8 0.8 0.8 1.0"/>
  </material>
  <material name="Opaque(128,128,128)">
    <color rgba="0.8 0.8 0.8 1.0"/>
  </material>
</robot>